[2020-01-26 19:35:58 +0300] [4441] [INFO] Starting gunicorn 19.9.0
[2020-01-26 19:35:58 +0300] [4441] [INFO] Listening at: http://81.177.174.185:58149 (4441)
[2020-01-26 19:35:58 +0300] [4441] [INFO] Using worker: threads
[2020-01-26 19:35:58 +0300] [4484] [INFO] Booting worker with pid: 4484
[2020-01-26 19:35:58 +0300] [4485] [INFO] Booting worker with pid: 4485
remote settings
remote settings
Traceback (most recent call last):
  File "/home/virtwww/w_pro5aa_022a0fbf/django-env/lib/python3.5/site-packages/django/db/backends/utils.py", line 84, in _execute
    return self.cursor.execute(sql, params)
psycopg2.errors.UniqueViolation: duplicate key value violates unique constraint "passport_app_formulaparametercategory_value_label_key"
DETAIL:  Key (value_label)=() already exists.


The above exception was the direct cause of the following exception:

Traceback (most recent call last):
  File "/home/virtwww/w_pro5aa_022a0fbf/property_passport/passport_app/views_items/parameters/parameters_view.py", line 84, in post
    parameter_formula.save()
  File "/home/virtwww/w_pro5aa_022a0fbf/django-env/lib/python3.5/site-packages/django/db/models/base.py", line 741, in save
    force_update=force_update, update_fields=update_fields)
  File "/home/virtwww/w_pro5aa_022a0fbf/django-env/lib/python3.5/site-packages/django/db/models/base.py", line 779, in save_base
    force_update, using, update_fields,
  File "/home/virtwww/w_pro5aa_022a0fbf/django-env/lib/python3.5/site-packages/django/db/models/base.py", line 870, in _save_table
    result = self._do_insert(cls._base_manager, using, fields, update_pk, raw)
  File "/home/virtwww/w_pro5aa_022a0fbf/django-env/lib/python3.5/site-packages/django/db/models/base.py", line 908, in _do_insert
    using=using, raw=raw)
  File "/home/virtwww/w_pro5aa_022a0fbf/django-env/lib/python3.5/site-packages/django/db/models/manager.py", line 82, in manager_method
    return getattr(self.get_queryset(), name)(*args, **kwargs)
  File "/home/virtwww/w_pro5aa_022a0fbf/django-env/lib/python3.5/site-packages/django/db/models/query.py", line 1186, in _insert
    return query.get_compiler(using=using).execute_sql(return_id)
  File "/home/virtwww/w_pro5aa_022a0fbf/django-env/lib/python3.5/site-packages/django/db/models/sql/compiler.py", line 1335, in execute_sql
    cursor.execute(sql, params)
  File "/home/virtwww/w_pro5aa_022a0fbf/django-env/lib/python3.5/site-packages/django/db/backends/utils.py", line 67, in execute
    return self._execute_with_wrappers(sql, params, many=False, executor=self._execute)
  File "/home/virtwww/w_pro5aa_022a0fbf/django-env/lib/python3.5/site-packages/django/db/backends/utils.py", line 76, in _execute_with_wrappers
    return executor(sql, params, many, context)
  File "/home/virtwww/w_pro5aa_022a0fbf/django-env/lib/python3.5/site-packages/django/db/backends/utils.py", line 84, in _execute
    return self.cursor.execute(sql, params)
  File "/home/virtwww/w_pro5aa_022a0fbf/django-env/lib/python3.5/site-packages/django/db/utils.py", line 89, in __exit__
    raise dj_exc_value.with_traceback(traceback) from exc_value
  File "/home/virtwww/w_pro5aa_022a0fbf/django-env/lib/python3.5/site-packages/django/db/backends/utils.py", line 84, in _execute
    return self.cursor.execute(sql, params)
django.db.utils.IntegrityError: duplicate key value violates unique constraint "passport_app_formulaparametercategory_value_label_key"
DETAIL:  Key (value_label)=() already exists.


